{
 "cells": [
  {
   "cell_type": "markdown",
   "id": "56d33dbc",
   "metadata": {},
   "source": [
    "# Python Advance Assignment  - 6"
   ]
  },
  {
   "cell_type": "markdown",
   "id": "b616819b",
   "metadata": {},
   "source": [
    "#### Q1. Describe three applications for exception processing.\n"
   ]
  },
  {
   "cell_type": "markdown",
   "id": "1e335fa2",
   "metadata": {},
   "source": [
    "Exception processing is a mechanism in Python (and other programming languages) for handling errors and exceptional situations in a program. Here are three common applications of exception processing:\n",
    "\n",
    "1. Error handling: When a program encounters an error or unexpected situation, it can raise an exception to signal that something has gone wrong. This allows the program to gracefully handle the error and take appropriate action, such as logging the error, displaying an error message to the user, or retrying the operation.\n",
    "\n",
    "2. Resource management: In some cases, a program needs to allocate and manage resources such as files, network connections, or database connections. If an exception occurs while using a resource, the program needs to release the resource to prevent resource leaks and other issues. By using exception processing, a program can ensure that resources are properly released even in the presence of exceptions.\n",
    "\n",
    "3. Control flow: In some cases, exception processing can be used to control the flow of a program. For example, a program may use exceptions to signal the end of a loop or to break out of a nested loop. Exceptions can also be used to implement custom control structures or to provide a way to return multiple values from a function.\n",
    "\n",
    "Overall, exception processing is a powerful mechanism that allows programs to gracefully handle errors and unexpected situations, manage resources, and control program flow."
   ]
  },
  {
   "cell_type": "markdown",
   "id": "2d6cabe6",
   "metadata": {},
   "source": [
    "#### Q2. What happens if you don&#39;t do something extra to treat an exception?"
   ]
  },
  {
   "cell_type": "markdown",
   "id": "d7e357b2",
   "metadata": {},
   "source": [
    "If an exception is raised in a Python program and there is no code to handle it, the program will terminate and display an error message to the user. This is because Python's default behavior when an unhandled exception occurs is to print a traceback message to the console and exit the program.\n",
    "\n",
    "For example, consider the following code that attempts to divide two numbers, but one of the numbers is zero:\n",
    "\n",
    "```\n",
    "a = 10\n",
    "b = 0\n",
    "result = a / b\n",
    "```\n",
    "\n",
    "When this code is executed, it will raise a `ZeroDivisionError` exception because we cannot divide by zero. If there is no code to handle this exception, the program will terminate and print a traceback message to the console\n",
    "\n",
    "\n",
    "To prevent the program from terminating and handle the exception in a more graceful way, we can use a `try`/`except` block to catch the exception and handle it appropriately."
   ]
  },
  {
   "cell_type": "markdown",
   "id": "89c8d018",
   "metadata": {},
   "source": [
    "#### Q3. What are your options for recovering from an exception in your script?"
   ]
  },
  {
   "cell_type": "markdown",
   "id": "5d323908",
   "metadata": {},
   "source": [
    "When an exception occurs in a Python script, there are several options for recovering from it, depending on the specific circumstances. Here are some common options:\n",
    "\n",
    "1. **Handle the exception and continue execution:** This is the most common approach to recovering from an exception. You can use a `try`/`except` block to catch the exception and handle it appropriately, then continue executing the rest of the script. For example:\n",
    "\n",
    "```\n",
    "try:\n",
    "    # some code that might raise an exception\n",
    "except SomeException:\n",
    "    # handle the exception and continue execution\n",
    "```\n",
    "\n",
    "2. **Raise a new exception:** If you catch an exception and cannot handle it properly, you can raise a new exception to indicate that something went wrong. This allows the higher-level code to handle the exception in a more appropriate way. For example:\n",
    "\n",
    "```\n",
    "try:\n",
    "    # some code that might raise an exception\n",
    "except SomeException:\n",
    "    # raise a new exception to indicate the problem\n",
    "    raise AnotherException(\"Something went wrong\")\n",
    "```\n",
    "\n",
    "3. **Exit the program:** In some cases, it may be appropriate to exit the program when an exception occurs, especially if the error is severe and there is no way to recover from it. You can use the `sys.exit()` function to terminate the program with a given exit code. For example:\n",
    "\n",
    "```\n",
    "import sys\n",
    "\n",
    "try:\n",
    "    # some code that might raise an exception\n",
    "except SomeException:\n",
    "    # print an error message and exit the program\n",
    "    print(\"An error occurred. Exiting.\")\n",
    "    sys.exit(1)\n",
    "```\n",
    "\n",
    "4. **Log the exception:** Finally, you can log the exception to a file or database for later analysis. This can be useful for debugging and identifying patterns in the errors that occur. You can use a logging library like `logging` to log the exception. For example:\n",
    "\n",
    "```\n",
    "import logging\n",
    "\n",
    "try:\n",
    "    # some code that might raise an exception\n",
    "except SomeException as e:\n",
    "    # log the exception to a file\n",
    "    logging.exception(\"An exception occurred: %s\", e)\n",
    "```"
   ]
  },
  {
   "cell_type": "markdown",
   "id": "482955ea",
   "metadata": {},
   "source": [
    "#### Q4. Describe two methods for triggering exceptions in your script."
   ]
  },
  {
   "cell_type": "markdown",
   "id": "f75f05cb",
   "metadata": {},
   "source": [
    "In Python, there are two ways to trigger an exception:\n",
    "\n",
    "1. Raise an exception manually using the `raise` statement:\n",
    "    \n",
    "   ```\n",
    "   raise Exception(\"Something went wrong!\")\n",
    "   ```\n",
    "\n",
    "   This will raise an `Exception` with the specified error message.\n",
    "\n",
    "2. Call a function that raises an exception when it encounters an error. For example, if you try to open a file that doesn't exist with the `open()` function, it will raise a `FileNotFoundError` exception:\n",
    "\n",
    "   ```\n",
    "   with open(\"nonexistent_file.txt\") as file:\n",
    "       # Code to handle the file here\n",
    "   ```\n",
    "\n",
    "   In this example, the `open()` function raises a `FileNotFoundError` exception because the file doesn't exist. This exception can be handled using a `try`/`except` block to avoid the script from crashing."
   ]
  },
  {
   "cell_type": "markdown",
   "id": "e4929465",
   "metadata": {},
   "source": [
    "#### Q5. Identify two methods for specifying actions to be executed at termination time, regardless of whether or not an exception exists."
   ]
  },
  {
   "cell_type": "markdown",
   "id": "2d877723",
   "metadata": {},
   "source": [
    "In Python, there are two methods for specifying actions to be executed at termination time, regardless of whether or not an exception exists:\n",
    "\n",
    "1. Using the `finally` block: \n",
    "\n",
    "   The `finally` block is used to specify a set of statements to be executed before the `try` block is exited, regardless of whether an exception was raised or not. This block is used for cleanup actions, such as closing a file or releasing a resource, that must be performed regardless of whether the code block runs successfully or not. Here's an example:\n",
    "\n",
    "   ```\n",
    "   try:\n",
    "       # Some code that might raise an exception\n",
    "   except Exception:\n",
    "       # Handle the exception here\n",
    "   finally:\n",
    "       # Cleanup code that will always execute, regardless of whether there was an exception or not\n",
    "   ```\n",
    "\n",
    "2. Using the `atexit` module:\n",
    "\n",
    "   The `atexit` module provides a simple interface for registering functions to be called when the Python interpreter exits. These functions are called \"exit handlers\" and they are called in the reverse order in which they were registered. Here's an example:\n",
    "\n",
    "   ```\n",
    "   import atexit\n",
    "\n",
    "   def cleanup():\n",
    "       # Code to be executed at termination time\n",
    "\n",
    "   atexit.register(cleanup)\n",
    "   ```\n",
    "\n",
    "   In this example, the `cleanup()` function is registered using the `atexit.register()` method, which specifies that the function should be called when the Python interpreter exits."
   ]
  },
  {
   "cell_type": "code",
   "execution_count": null,
   "id": "f7ba4983",
   "metadata": {},
   "outputs": [],
   "source": []
  }
 ],
 "metadata": {
  "kernelspec": {
   "display_name": "Python 3 (ipykernel)",
   "language": "python",
   "name": "python3"
  },
  "language_info": {
   "codemirror_mode": {
    "name": "ipython",
    "version": 3
   },
   "file_extension": ".py",
   "mimetype": "text/x-python",
   "name": "python",
   "nbconvert_exporter": "python",
   "pygments_lexer": "ipython3",
   "version": "3.9.7"
  }
 },
 "nbformat": 4,
 "nbformat_minor": 5
}
